Traceback (most recent call last):
  File "C:\Users\tbeucler\.conda\envs\JB\lib\site-packages\jupyter_cache\executors\utils.py", line 58, in single_nb_execution
    executenb(
  File "C:\Users\tbeucler\.conda\envs\JB\lib\site-packages\nbclient\client.py", line 1305, in execute
    return NotebookClient(nb=nb, resources=resources, km=km, **kwargs).execute()
  File "C:\Users\tbeucler\.conda\envs\JB\lib\site-packages\jupyter_core\utils\__init__.py", line 166, in wrapped
    return loop.run_until_complete(inner)
  File "C:\Users\tbeucler\.conda\envs\JB\lib\asyncio\base_events.py", line 647, in run_until_complete
    return future.result()
  File "C:\Users\tbeucler\.conda\envs\JB\lib\site-packages\nbclient\client.py", line 705, in async_execute
    await self.async_execute_cell(
  File "C:\Users\tbeucler\.conda\envs\JB\lib\site-packages\nbclient\client.py", line 1058, in async_execute_cell
    await self._check_raise_for_error(cell, cell_index, exec_reply)
  File "C:\Users\tbeucler\.conda\envs\JB\lib\site-packages\nbclient\client.py", line 914, in _check_raise_for_error
    raise CellExecutionError.from_cell_and_msg(cell, exec_reply_content)
nbclient.exceptions.CellExecutionError: An error occurred while executing the following cell:
------------------
h = Hurricane('florence', 4, -46)
print(h,h.name)
h = Hurricane('Ida', 5, 300)
------------------

----- stdout -----
<__main__.Hurricane object at 0x000001C35D226EE0> FLORENCE
------------------

[1;31m---------------------------------------------------------------------------[0m
[1;31mValueError[0m                                Traceback (most recent call last)
Cell [1;32mIn[42], line 3[0m
[0;32m      1[0m h [38;5;241m=[39m Hurricane([38;5;124m'[39m[38;5;124mflorence[39m[38;5;124m'[39m, [38;5;241m4[39m, [38;5;241m-[39m[38;5;241m46[39m)
[0;32m      2[0m [38;5;28mprint[39m(h,h[38;5;241m.[39mname)
[1;32m----> 3[0m h [38;5;241m=[39m [43mHurricane[49m[43m([49m[38;5;124;43m'[39;49m[38;5;124;43mIda[39;49m[38;5;124;43m'[39;49m[43m,[49m[43m [49m[38;5;241;43m5[39;49m[43m,[49m[43m [49m[38;5;241;43m300[39;49m[43m)[49m

Cell [1;32mIn[41], line 8[0m, in [0;36mHurricane.__init__[1;34m(self, name, category, lon)[0m
[0;32m      5[0m [38;5;28mself[39m[38;5;241m.[39mcategory [38;5;241m=[39m [38;5;28mint[39m(category)
[0;32m      7[0m [38;5;28;01mif[39;00m lon [38;5;241m>[39m [38;5;241m180[39m [38;5;129;01mor[39;00m lon [38;5;241m<[39m [38;5;241m-[39m[38;5;241m180[39m:
[1;32m----> 8[0m     [38;5;28;01mraise[39;00m [38;5;167;01mValueError[39;00m([38;5;124mf[39m[38;5;124m'[39m[38;5;124mInvalid lon [39m[38;5;132;01m{[39;00mlon[38;5;132;01m}[39;00m[38;5;124m'[39m)
[0;32m      9[0m [38;5;28mself[39m[38;5;241m.[39mlon [38;5;241m=[39m lon

[1;31mValueError[0m: Invalid lon 300

